## 에러 및 예외처리

예외는 우리가 원하는 과정이 아닐 때 에러를 발생 시키는 것을 처리하는 것이라 볼 수 있다. 쉬운 예를 들어서...

    function sum(x,y) {
        if( typeof x !== 'number' || typeof y !== 'number'){
            throw '숫자가 아닙니다.';
        }
        return x+y;
    }
    console.log(sum('a',2))

를 해보면 Uncaught '숫자가 아닙니다' 라고 뜨는걸 볼 수 있는데 두 인자 모두 'number'형을 받기를 원했는데 아닌 것이 들어와서 에러를 발생 시킨 것이다.
이런 에러를 발생시키는 다른 예를 봤을 때

    function f2() {
        console.log('f2 start);
        throw new Error('에러');
        console.log('f2 end);
    }

    function f1() {
        console.log('f1 start);
        f2();
        console.log('f1 end');
    }

    console.log('will : f1');
    f1();
    console.log('did: f1');

이렇게 되어있으면 에러가 발생한 이후로부터는 다 실행이 되지 않는다. 왜냐하면 예외처리를 해주지 않았기 때문에 에러가 난 뒤의 상황은 다 실행이 되지 않고 콜스택에서 빠져나가 버린다.
이것을 해결하기 위해서 try, catch를 사용한다.

    function f2() {
        console.log('f2 start);
        throw new Error('에러');
        console.log('f2 end);
    }

    function f1() {
        console.log('f1 start);
        try {
            f2();
        }
        catch(e){
            console.log(e);
        }
        console.log('f1 end');
    }

    console.log('will : f1');
    f1();
    console.log('did: f1');

에러가 날 것 같은 코드를 try에 넣고 발생한 에러를 catch에서 e 로 받아서 console.log를 실행시키는 코드다. 그러면 에러가 발생한다음 'f2 end'라는 문구는 출력 되지 않지만 예외처리를 하고 난 뒤의 'f1 end'와 'did f1'이라는 문구는 출력 되게 된다.


## 비동기처리에서의 에러 및 예외

비동기처리 함수에서는 즉 promise와 async, await에서는 예외처리를 다르게 하는데 알아보도록 하겠다.

    function wait(sec) {
        return new Promise((resolve, reject) => {
            setTimeout(() => {
                reject('error!);
            }, sec * 1000);
        });
    } 

    wait(3)
        .then(
            ()=> {
                console.log('done!!!!');
            },
            e => {
                console.log('1nd Error!');
            }
        }
    
또는

    wait(3).catch(e => {
        console.log(e)
    })

이런식으로 try, catch를 사용하지 않고 then 안에서 하거나 catch만을 이용해서 할 수 있따.

async await의 예외처리를 알아보기전에 잠시 async await부터 보면

    async function myAsyncFun(){
        return 'done!';
    }

    function myPromiseFun() {
        return new Promise((resolve, reject) => {
            resolve('done!);
        })
    }

    const result = myAsyncFun();
    console.log(result);

    const result2 = myPromiseFun();
    console.log(result2);

이렇게 하면 result와 result2가 둘다 Promise에 resolved : 'done!'이 된다.
그니깐 async 함수는 Promise의 resolve를 반환해준다고 보면 된다.

그런데 Promise에서는 reject를 쓰면 에러처리가 되는데 async에서는 어떻게 해야하나...

async에서는 throw를 해주면 reject로 된다. 
throw로 에러를 주지만 에러를 잡는 방법 즉 예외를 처리하는 방법은 Promise와 동일하게 .catch로 잡으면 된다. 왜냐하면 똑같이 Promise를 반환하기 때문에 ..

    async function myAsyncFun(){
        throw 'myAsyncError!';
    }

    function myPromiseFun() {
        return new Promise((resolve, reject) => {
            reject('myError!');
        });
    }

    const result = myAsyncFun().catch(e => {
        console.error(e);
    });

    const result2 = myPromiseFun().catch(e => {
        console.error(e);
    });

이런식으로 하면 된다.

    function wait(sec) {
        return new Promise((resolve, reject) => {
            setTimeout(() => {
                reject('wait Error');
            }, sec * 1000);
        });
    }

    async function myAsyncFun() {
        console.log(new Date());
        await wait(3).catch(e => {
            console.error(e);
        })
        console.log(new Date());
    }

    myAsyncFun().catch((e) => {
        console.error(e);
    })

일단 await를 쓰지 않고 위 코드를 실행을 시키면 Date 시간이 거의 비슷하게 뜬다. 왜냐하면 wait가 비동기적으로 실행이 되기 때문에 wait()은 큐로 보내지고 콜스택에는 먼저 console.log들이 들어가기 때문이다. 그래서 콜스택이 끝나고 3초가 지나게 된다. await를 쓰면 3초를 기다리고 다음 콜스택을 실행하게 되기 때문에 3초뒤에 밑의 date가 찍히게 된다. await를 쓰면 throw로 예외를 보내기 때문에 .catch로 예외를 잡아도 되고 try catch로 잡아도 되더라. async 함수 안에서 syntax 오류나 여러 오류들을 잡으려면 async가 Promise를 반환하기 때문에 try catch로는 잡히지 않고, .catch를 하여야 잡을 수 있다. 


뭔가 알 것 같은데 잘 모르겠기도 하고... 그래서 비동기 처리에 대해서 더 공부를 해야 될 것 같다는 생각이 들었다. Promise를 완전 정복하고 싶어졌다...